<?xml version="1.0"?>
<robot name="six_axis_arm">

  <link name="base_link">
    <visual>
      <geometry>
        <cylinder radius="0.15" length="0.1"/>
      </geometry>
      <origin xyz="0 0 0.05" rpy="0 0 0"/>
      <material name="dark_gray">
        <color rgba="0.3 0.3 0.3 1"/>
      </material>
    </visual>
    <collision>
      <geometry>
        <cylinder radius="0.15" length="0.1"/>
      </geometry>
      <origin xyz="0 0 0.05" rpy="0 0 0"/>
    </collision>
    <inertial>
      <mass value="2.0"/>
      <origin xyz="0 0 0.05"/>
      <inertia ixx="0.01" ixy="0" ixz="0" iyy="0.01" iyz="0" izz="0.02"/>
    </inertial>
  </link>

  <link name="link1">
    <visual>
      <geometry>
        <box size="0.1 0.1 0.4"/>
      </geometry>
      <origin xyz="0 0 0.2"/>
      <material name="blue">
        <color rgba="0 0 0.8 1"/>
      </material>
    </visual>
    <collision>
      <geometry>
        <box size="0.1 0.1 0.4"/>
      </geometry>
      <origin xyz="0 0 0.2"/>
    </collision>
    <inertial>
      <mass value="1.5"/>
      <origin xyz="0 0 0.2"/>
      <inertia ixx="0.005" ixy="0" ixz="0" iyy="0.005" iyz="0" izz="0.001"/>
    </inertial>
  </link>

  <joint name="joint1" type="revolute">
    <parent link="base_link"/>
    <child link="link1"/>
    <origin xyz="0 0 0.1" rpy="0 0 0"/>
    <axis xyz="0 0 1"/>
    <limit lower="-3.14" upper="3.14" effort="100" velocity="10"/>
  </joint>

  <link name="link2">
    <visual>
      <geometry>
        <box size="0.1 0.1 0.5"/>
      </geometry>
      <origin xyz="0 0 0.25"/>
      <material name="green">
        <color rgba="0 0.8 0 1"/>
      </material>
    </visual>
    <collision>
      <geometry>
        <box size="0.1 0.1 0.5"/>
      </geometry>
      <origin xyz="0 0 0.25"/>
    </collision>
    <inertial>
      <mass value="1.0"/>
      <origin xyz="0 0 0.25"/>
      <inertia ixx="0.003" ixy="0" ixz="0" iyy="0.003" iyz="0" izz="0.001"/>
    </inertial>
  </link>

  <joint name="joint2" type="revolute">
    <parent link="link1"/>
    <child link="link2"/>
    <origin xyz="0 0 0.4" rpy="0 0 0"/>
    <axis xyz="0 1 0"/>
    <limit lower="-1.57" upper="1.57" effort="100" velocity="10"/>
  </joint>

  <link name="link3">
    <visual>
      <geometry>
        <box size="0.08 0.08 0.4"/>
      </geometry>
      <origin xyz="0 0 0.2"/>
      <material name="red">
        <color rgba="0.8 0 0 1"/>
      </material>
    </visual>
    <collision>
      <geometry>
        <box size="0.08 0.08 0.4"/>
      </geometry>
      <origin xyz="0 0 0.2"/>
    </collision>
    <inertial>
      <mass value="0.7"/>
      <origin xyz="0 0 0.2"/>
      <inertia ixx="0.002" ixy="0" ixz="0" iyy="0.002" iyz="0" izz="0.0005"/>
    </inertial>
  </link>

  <joint name="joint3" type="revolute">
    <parent link="link2"/>
    <child link="link3"/>
    <origin xyz="0 0 0.5" rpy="0 0 0"/>
    <axis xyz="0 1 0"/>
    <limit lower="-2.0" upper="0.5" effort="100" velocity="10"/>
  </joint>

  <link name="link4">
    <visual>
      <geometry>
        <box size="0.06 0.06 0.15"/>
      </geometry>
      <origin xyz="0 0 0.075"/>
      <material name="purple">
        <color rgba="0.5 0 0.5 1"/>
      </material>
    </visual>
    <collision>
      <geometry>
        <box size="0.06 0.06 0.15"/>
      </geometry>
      <origin xyz="0 0 0.075"/>
    </collision>
    <inertial>
      <mass value="0.3"/>
      <origin xyz="0 0 0.075"/>
      <inertia ixx="0.0005" ixy="0" ixz="0" iyy="0.0005" iyz="0" izz="0.0001"/>
    </inertial>
  </link>

  <joint name="joint4" type="revolute">
    <parent link="link3"/>
    <child link="link4"/>
    <origin xyz="0 0 0.4" rpy="0 0 0"/>
    <axis xyz="0 0 1"/>
    <limit lower="-3.14" upper="3.14" effort="50" velocity="5"/>
  </joint>

  <link name="link5">
    <visual>
      <geometry>
        <box size="0.05 0.05 0.15"/>
      </geometry>
      <origin xyz="0 0 0.075"/>
      <material name="orange">
        <color rgba="1 0.5 0 1"/>
      </material>
    </visual>
    <collision>
      <geometry>
        <box size="0.05 0.05 0.15"/>
      </geometry>
      <origin xyz="0 0 0.075"/>
    </collision>
    <inertial>
      <mass value="0.2"/>
      <origin xyz="0 0 0.075"/>
      <inertia ixx="0.0003" ixy="0" ixz="0" iyy="0.0003" iyz="0" izz="0.00005"/>
    </inertial>
  </link>

  <joint name="joint5" type="revolute">
    <parent link="link4"/>
    <child link="link5"/>
    <origin xyz="0 0 0.15" rpy="0 0 0"/>
    <axis xyz="0 1 0"/>
    <limit lower="-1.57" upper="1.57" effort="50" velocity="5"/>
  </joint>

  <link name="link6">
    <visual>
      <geometry>
        <box size="0.04 0.04 0.1"/>
      </geometry>
      <origin xyz="0 0 0.05"/>
      <material name="yellow">
        <color rgba="1 1 0 1"/>
      </material>
    </visual>
    <collision>
      <geometry>
        <box size="0.04 0.04 0.1"/>
      </geometry>
      <origin xyz="0 0 0.05"/>
    </collision>
    <inertial>
      <mass value="0.1"/>
      <origin xyz="0 0 0.05"/>
      <inertia ixx="0.0001" ixy="0" ixz="0" iyy="0.0001" iyz="0" izz="0.00001"/>
    </inertial>
  </link>

  <joint name="joint6" type="revolute">
    <parent link="link5"/>
    <child link="link6"/>
    <origin xyz="0 0 0.15" rpy="0 0 0"/>
    <axis xyz="0 0 1"/>
    <limit lower="-3.14" upper="3.14" effort="50" velocity="5"/>
  </joint>

  <link name="end_effector_tool">
    <visual>
      <geometry>
        <box size="0.05 0.05 0.05"/>
      </geometry>
      <origin xyz="0 0 0.025"/>
      <material name="white">
        <color rgba="1 1 1 1"/>
      </material>
    </visual>
    <collision>
      <geometry>
        <box size="0.05 0.05 0.05"/>
      </geometry>
      <origin xyz="0 0 0.025"/>
    </collision>
    <inertial>
      <mass value="0.05"/>
      <origin xyz="0 0 0.025"/>
      <inertia ixx="0.00001" ixy="0" ixz="0" iyy="0.00001" iyz="0" izz="0.00001"/>
    </inertial>
  </link>

  <joint name="fixed_tool_joint" type="fixed">
    <parent link="link6"/>
    <child link="end_effector_tool"/>
    <origin xyz="0 0 0.1" rpy="0 0 0"/>
  </joint>

</robot>