<?xml version="1.0"?>
<robot name="quadruped">

  <link name="body">
    <visual>
      <geometry>
        <box size="0.3 0.15 0.05"/>
      </geometry>
      <origin xyz="0 0 0" rpy="0 0 0"/>
      <material name="gray">
        <color rgba="0.7 0.7 0.7 1"/>
      </material>
    </visual>
    <collision>
      <geometry>
        <box size="0.3 0.15 0.05"/>
      </geometry>
      <origin xyz="0 0 0" rpy="0 0 0"/>
    </collision>
    <inertial>
      <mass value="2.0"/>
      <origin xyz="0 0 0"/>
      <inertia ixx="0.01" ixy="0" ixz="0" iyy="0.01" iyz="0" izz="0.01"/>
    </inertial>
  </link>

  <link name="fr_hip_link">
    <visual>
      <geometry>
        <box size="0.05 0.05 0.05"/>
      </geometry>
      <origin xyz="0 0 0" rpy="0 0 0"/>
      <material name="red">
        <color rgba="1 0 0 1"/>
      </material>
    </visual>
    <collision>
      <geometry>
        <box size="0.05 0.05 0.05"/>
      </geometry>
      <origin xyz="0 0 0" rpy="0 0 0"/>
    </collision>
    <inertial>
      <mass value="0.1"/>
      <origin xyz="0 0 0"/>
      <inertia ixx="0.0001" ixy="0" ixz="0" iyy="0.0001" iyz="0" izz="0.0001"/>
    </inertial>
  </link>
  <joint name="fr_hip_joint" type="revolute">
    <parent link="body"/>
    <child link="fr_hip_link"/>
    <origin xyz="0.12 -0.075 0" rpy="0 0 0"/>
    <axis xyz="0 1 0"/> <limit lower="-1.0" upper="1.0" effort="10" velocity="10"/>
  </joint>

  <link name="fr_thigh_link">
    <visual>
      <geometry>
        <cylinder radius="0.02" length="0.15"/>
      </geometry>
      <origin xyz="0 0 -0.075" rpy="0 0 0"/>
      <material name="blue">
        <color rgba="0 0 1 1"/>
      </material>
    </visual>
    <collision>
      <geometry>
        <cylinder radius="0.02" length="0.15"/>
      </geometry>
      <origin xyz="0 0 -0.075" rpy="0 0 0"/>
    </collision>
    <inertial>
      <mass value="0.1"/>
      <origin xyz="0 0 -0.075"/>
      <inertia ixx="0.0001" ixy="0" ixz="0" iyy="0.0001" iyz="0" izz="0.00001"/>
    </inertial>
  </link>
  <joint name="fr_thigh_joint" type="revolute">
    <parent link="fr_hip_link"/>
    <child link="fr_thigh_link"/>
    <origin xyz="0 0 0" rpy="0 0 0"/>
    <axis xyz="1 0 0"/> <limit lower="-0.5" upper="0.5" effort="10" velocity="10"/>
  </joint>

  <link name="fr_calf_link">
    <visual>
      <geometry>
        <cylinder radius="0.015" length="0.15"/>
      </geometry>
      <origin xyz="0 0 -0.075" rpy="0 0 0"/>
      <material name="green">
        <color rgba="0 1 0 1"/>
      </material>
    </visual>
    <collision>
      <geometry>
        <cylinder radius="0.015" length="0.15"/>
      </geometry>
      <origin xyz="0 0 -0.075" rpy="0 0 0"/>
    </collision>
    <inertial>
      <mass value="0.05"/>
      <origin xyz="0 0 -0.075"/>
      <inertia ixx="0.00005" ixy="0" ixz="0" iyy="0.00005" iyz="0" izz="0.000005"/>
    </inertial>
  </link>
  <joint name="fr_calf_joint" type="revolute">
    <parent link="fr_thigh_link"/>
    <child link="fr_calf_link"/>
    <origin xyz="0 0 -0.15" rpy="0 0 0"/>
    <axis xyz="0 1 0"/> <limit lower="-2.0" upper="0.0" effort="10" velocity="10"/>
  </joint>

  <link name="fl_hip_link">
    <visual>
      <geometry>
        <box size="0.05 0.05 0.05"/>
      </geometry>
      <origin xyz="0 0 0" rpy="0 0 0"/>
      <material name="red"/>
    </visual>
    <collision>
      <geometry>
        <box size="0.05 0.05 0.05"/>
      </geometry>
      <origin xyz="0 0 0" rpy="0 0 0"/>
    </collision>
    <inertial>
      <mass value="0.1"/>
      <origin xyz="0 0 0"/>
      <inertia ixx="0.0001" ixy="0" ixz="0" iyy="0.0001" iyz="0" izz="0.0001"/>
    </inertial>
  </link>
  <joint name="fl_hip_joint" type="revolute">
    <parent link="body"/>
    <child link="fl_hip_link"/>
    <origin xyz="0.12 0.075 0" rpy="0 0 0"/>
    <axis xyz="0 1 0"/>
    <limit lower="-1.0" upper="1.0" effort="10" velocity="10"/>
  </joint>

  <link name="fl_thigh_link">
    <visual>
      <geometry>
        <cylinder radius="0.02" length="0.15"/>
      </geometry>
      <origin xyz="0 0 -0.075" rpy="0 0 0"/>
      <material name="blue"/>
    </visual>
    <collision>
      <geometry>
        <cylinder radius="0.02" length="0.15"/>
      </geometry>
      <origin xyz="0 0 -0.075" rpy="0 0 0"/>
    </collision>
    <inertial>
      <mass value="0.1"/>
      <origin xyz="0 0 -0.075"/>
      <inertia ixx="0.0001" ixy="0" ixz="0" iyy="0.0001" iyz="0" izz="0.00001"/>
    </inertial>
  </link>
  <joint name="fl_thigh_joint" type="revolute">
    <parent link="fl_hip_link"/>
    <child link="fl_thigh_link"/>
    <origin xyz="0 0 0" rpy="0 0 0"/>
    <axis xyz="1 0 0"/>
    <limit lower="-0.5" upper="0.5" effort="10" velocity="10"/>
  </joint>

  <link name="fl_calf_link">
    <visual>
      <geometry>
        <cylinder radius="0.015" length="0.15"/>
      </geometry>
      <origin xyz="0 0 -0.075" rpy="0 0 0"/>
      <material name="green"/>
    </visual>
    <collision>
      <geometry>
        <cylinder radius="0.015" length="0.15"/>
      </geometry>
      <origin xyz="0 0 -0.075" rpy="0 0 0"/>
    </collision>
    <inertial>
      <mass value="0.05"/>
      <origin xyz="0 0 -0.075"/>
      <inertia ixx="0.00005" ixy="0" ixz="0" iyy="0.00005" iyz="0" izz="0.000005"/>
    </inertial>
  </link>
  <joint name="fl_calf_joint" type="revolute">
    <parent link="fl_thigh_link"/>
    <child link="fl_calf_link"/>
    <origin xyz="0 0 -0.15" rpy="0 0 0"/>
    <axis xyz="0 1 0"/>
    <limit lower="-2.0" upper="0.0" effort="10" velocity="10"/>
  </joint>

  <link name="rr_hip_link">
    <visual>
      <geometry>
        <box size="0.05 0.05 0.05"/>
      </geometry>
      <origin xyz="0 0 0" rpy="0 0 0"/>
      <material name="red"/>
    </visual>
    <collision>
      <geometry>
        <box size="0.05 0.05 0.05"/>
      </geometry>
      <origin xyz="0 0 0" rpy="0 0 0"/>
    </collision>
    <inertial>
      <mass value="0.1"/>
      <origin xyz="0 0 0"/>
      <inertia ixx="0.0001" ixy="0" ixz="0" iyy="0.0001" iyz="0" izz="0.0001"/>
    </inertial>
  </link>
  <joint name="rr_hip_joint" type="revolute">
    <parent link="body"/>
    <child link="rr_hip_link"/>
    <origin xyz="-0.12 -0.075 0" rpy="0 0 0"/>
    <axis xyz="0 1 0"/>
    <limit lower="-1.0" upper="1.0" effort="10" velocity="10"/>
  </joint>

  <link name="rr_thigh_link">
    <visual>
      <geometry>
        <cylinder radius="0.02" length="0.15"/>
      </geometry>
      <origin xyz="0 0 -0.075" rpy="0 0 0"/>
      <material name="blue"/>
    </visual>
    <collision>
      <geometry>
        <cylinder radius="0.02" length="0.15"/>
      </geometry>
      <origin xyz="0 0 -0.075" rpy="0 0 0"/>
    </collision>
    <inertial>
      <mass value="0.1"/>
      <origin xyz="0 0 -0.075"/>
      <inertia ixx="0.0001" ixy="0" ixz="0" iyy="0.0001" iyz="0" izz="0.00001"/>
    </inertial>
  </link>
  <joint name="rr_thigh_joint" type="revolute">
    <parent link="rr_hip_link"/>
    <child link="rr_thigh_link"/>
    <origin xyz="0 0 0" rpy="0 0 0"/>
    <axis xyz="1 0 0"/>
    <limit lower="-0.5" upper="0.5" effort="10" velocity="10"/>
  </joint>

  <link name="rr_calf_link">
    <visual>
      <geometry>
        <cylinder radius="0.015" length="0.15"/>
      </geometry>
      <origin xyz="0 0 -0.075" rpy="0 0 0"/>
      <material name="green"/>
    </visual>
    <collision>
      <geometry>
        <cylinder radius="0.015" length="0.15"/>
      </geometry>
      <origin xyz="0 0 -0.075" rpy="0 0 0"/>
    </collision>
    <inertial>
      <mass value="0.05"/>
      <origin xyz="0 0 -0.075"/>
      <inertia ixx="0.00005" ixy="0" ixz="0" iyy="0.00005" iyz="0" izz="0.000005"/>
    </inertial>
  </link>
  <joint name="rr_calf_joint" type="revolute">
    <parent link="rr_thigh_link"/>
    <child link="rr_calf_link"/>
    <origin xyz="0 0 -0.15" rpy="0 0 0"/>
    <axis xyz="0 1 0"/>
    <limit lower="-2.0" upper="0.0" effort="10" velocity="10"/>
  </joint>

  <link name="rl_hip_link">
    <visual>
      <geometry>
        <box size="0.05 0.05 0.05"/>
      </geometry>
      <origin xyz="0 0 0" rpy="0 0 0"/>
      <material name="red"/>
    </visual>
    <collision>
      <geometry>
        <box size="0.05 0.05 0.05"/>
      </geometry>
      <origin xyz="0 0 0" rpy="0 0 0"/>
    </collision>
    <inertial>
      <mass value="0.1"/>
      <origin xyz="0 0 0"/>
      <inertia ixx="0.0001" ixy="0" ixz="0" iyy="0.0001" iyz="0" izz="0.0001"/>
    </inertial>
  </link>
  <joint name="rl_hip_joint" type="revolute">
    <parent link="body"/>
    <child link="rl_hip_link"/>
    <origin xyz="-0.12 0.075 0" rpy="0 0 0"/>
    <axis xyz="0 1 0"/>
    <limit lower="-1.0" upper="1.0" effort="10" velocity="10"/>
  </joint>

  <link name="rl_thigh_link">
    <visual>
      <geometry>
        <cylinder radius="0.02" length="0.15"/>
      </geometry>
      <origin xyz="0 0 -0.075" rpy="0 0 0"/>
      <material name="blue"/>
    </visual>
    <collision>
      <geometry>
        <cylinder radius="0.02" length="0.15"/>
      </geometry>
      <origin xyz="0 0 -0.075" rpy="0 0 0"/>
    </collision>
    <inertial>
      <mass value="0.1"/>
      <origin xyz="0 0 -0.075"/>
      <inertia ixx="0.0001" ixy="0" ixz="0" iyy="0.0001" iyz="0" izz="0.00001"/>
    </inertial>
  </link>
  <joint name="rl_thigh_joint" type="revolute">
    <parent link="rl_hip_link"/>
    <child link="rl_thigh_link"/>
    <origin xyz="0 0 0" rpy="0 0 0"/>
    <axis xyz="1 0 0"/>
    <limit lower="-0.5" upper="0.5" effort="10" velocity="10"/>
  </joint>

  <link name="rl_calf_link">
    <visual>
      <geometry>
        <cylinder radius="0.015" length="0.15"/>
      </geometry>
      <origin xyz="0 0 -0.075" rpy="0 0 0"/>
      <material name="green"/>
    </visual>
    <collision>
      <geometry>
        <cylinder radius="0.015" length="0.15"/>
      </geometry>
      <origin xyz="0 0 -0.075" rpy="0 0 0"/>
    </collision>
    <inertial>
      <mass value="0.05"/>
      <origin xyz="0 0 -0.075"/>
      <inertia ixx="0.00005" ixy="0" ixz="0" iyy="0.00005" iyz="0" izz="0.000005"/>
    </inertial>
  </link>
  <joint name="rl_calf_joint" type="revolute">
    <parent link="rl_thigh_link"/>
    <child link="rl_calf_link"/>
    <origin xyz="0 0 -0.15" rpy="0 0 0"/>
    <axis xyz="0 1 0"/>
    <limit lower="-2.0" upper="0.0" effort="10" velocity="10"/>
  </joint>

</robot>