<?xml version="1.0"?>
<robot name="humanoid">

  <link name="torso">
    <visual>
      <geometry>
        <box size="0.15 0.1 0.3"/>
      </geometry>
      <origin xyz="0 0 0" rpy="0 0 0"/>
      <material name="red">
        <color rgba="1 0 0 1"/>
      </material>
    </visual>
    <collision>
      <geometry>
        <box size="0.15 0.1 0.3"/>
      </geometry>
      <origin xyz="0 0 0" rpy="0 0 0"/>
    </collision>
    <inertial>
      <mass value="5.0"/>
      <origin xyz="0 0 0"/>
      <inertia ixx="0.1" ixy="0" ixz="0" iyy="0.1" iyz="0" izz="0.1"/>
    </inertial>
  </link>

  <link name="head">
    <visual>
      <geometry>
        <sphere radius="0.07"/>
      </geometry>
      <origin xyz="0 0 0" rpy="0 0 0"/>
      <material name="blue">
        <color rgba="0 0 1 1"/>
      </material>
    </visual>
    <collision>
      <geometry>
        <sphere radius="0.07"/>
      </geometry>
      <origin xyz="0 0 0" rpy="0 0 0"/>
    </collision>
    <inertial>
      <mass value="0.5"/>
      <origin xyz="0 0 0"/>
      <inertia ixx="0.001" ixy="0" ixz="0" iyy="0.001" iyz="0" izz="0.001"/>
    </inertial>
  </link>
  <joint name="neck_joint" type="revolute">
    <parent link="torso"/>
    <child link="head"/>
    <origin xyz="0 0 0.18" rpy="0 0 0"/>
    <axis xyz="0 0 1"/>
    <limit lower="-1.57" upper="1.57" effort="10" velocity="10"/>
  </joint>


  <link name="right_hip_link">
    <visual>
      <geometry>
        <box size="0.08 0.08 0.08"/>
      </geometry>
      <origin xyz="0 0 0" rpy="0 0 0"/>
      <material name="green">
        <color rgba="0 1 0 1"/>
      </material>
    </visual>
    <collision>
      <geometry>
        <box size="0.08 0.08 0.08"/>
      </geometry>
      <origin xyz="0 0 0" rpy="0 0 0"/>
    </collision>
    <inertial>
      <mass value="0.5"/>
      <origin xyz="0 0 0"/>
      <inertia ixx="0.001" ixy="0" ixz="0" iyy="0.001" iyz="0" izz="0.001"/>
    </inertial>
  </link>
  <joint name="right_hip_pitch_joint" type="revolute">
    <parent link="torso"/>
    <child link="right_hip_link"/>
    <origin xyz="0 -0.07 0.0" rpy="0 0 0"/>
    <axis xyz="0 1 0"/>
    <limit lower="-1.57" upper="1.57" effort="100" velocity="10"/>
  </joint>

  <link name="right_thigh_link">
    <visual>
      <geometry>
        <cylinder radius="0.04" length="0.25"/> </geometry>
      <origin xyz="0 0 -0.125" rpy="0 0 0"/>
      <material name="cyan">
        <color rgba="0 1 1 1"/>
      </material>
    </visual>
    <collision>
      <geometry>
        <cylinder radius="0.04" length="0.25"/> </geometry>
      <origin xyz="0 0 -0.125" rpy="0 0 0"/>
    </collision>
    <inertial>
      <mass value="1.0"/>
      <origin xyz="0 0 -0.125"/>
      <inertia ixx="0.005" ixy="0" ixz="0" iyy="0.005" iyz="0" izz="0.0001"/>
    </inertial>
  </link>
  <joint name="right_knee_joint" type="revolute">
    <parent link="right_hip_link"/>
    <child link="right_thigh_link"/>
    <origin xyz="0 0 -0.04" rpy="0 0 0"/>
    <axis xyz="0 1 0"/>
    <limit lower="-1.57" upper="1.57" effort="100" velocity="10"/>
  </joint>

  <link name="right_calf_link">
    <visual>
      <geometry>
        <cylinder radius="0.03" length="0.2"/> </geometry>
      <origin xyz="0 0 -0.1" rpy="0 0 0"/>
      <material name="magenta">
        <color rgba="1 0 1 1"/>
      </material>
    </visual>
    <collision>
      <geometry>
        <cylinder radius="0.03" length="0.2"/> </geometry>
      <origin xyz="0 0 -0.1" rpy="0 0 0"/>
    </collision>
    <inertial>
      <mass value="0.7"/>
      <origin xyz="0 0 -0.1"/>
      <inertia ixx="0.003" ixy="0" ixz="0" iyy="0.003" iyz="0" izz="0.00005"/>
    </inertial>
  </link>
  <joint name="right_ankle_joint" type="revolute">
    <parent link="right_thigh_link"/>
    <child link="right_calf_link"/>
    <origin xyz="0 0 -0.25" rpy="0 0 0"/>
    <axis xyz="0 1 0"/>
    <limit lower="-1.57" upper="1.57" effort="100" velocity="10"/>
  </joint>


  <link name="left_hip_link">
    <visual>
      <geometry>
        <box size="0.08 0.08 0.08"/>
      </geometry>
      <origin xyz="0 0 0" rpy="0 0 0"/>
      <material name="green"/>
    </visual>
    <collision>
      <geometry>
        <box size="0.08 0.08 0.08"/>
      </geometry>
      <origin xyz="0 0 0" rpy="0 0 0"/>
    </collision>
    <inertial>
      <mass value="0.5"/>
      <origin xyz="0 0 0"/>
      <inertia ixx="0.001" ixy="0" ixz="0" iyy="0.001" iyz="0" izz="0.001"/>
    </inertial>
  </link>
  <joint name="left_hip_pitch_joint" type="revolute">
    <parent link="torso"/>
    <child link="left_hip_link"/>
    <origin xyz="0 0.07 0.0" rpy="0 0 0"/>
    <axis xyz="0 1 0"/>
    <limit lower="-1.57" upper="1.57" effort="100" velocity="10"/>
  </joint>

  <link name="left_thigh_link">
    <visual>
      <geometry>
        <cylinder radius="0.04" length="0.25"/> </geometry>
      <origin xyz="0 0 -0.125" rpy="0 0 0"/>
      <material name="cyan"/>
    </visual>
    <collision>
      <geometry>
        <cylinder radius="0.04" length="0.25"/> </geometry>
      <origin xyz="0 0 -0.125" rpy="0 0 0"/>
    </collision>
    <inertial>
      <mass value="1.0"/>
      <origin xyz="0 0 -0.125"/>
      <inertia ixx="0.005" ixy="0" ixz="0" iyy="0.005" iyz="0" izz="0.0001"/>
    </inertial>
  </link>
  <joint name="left_knee_joint" type="revolute">
    <parent link="left_hip_link"/>
    <child link="left_thigh_link"/>
    <origin xyz="0 0 -0.04" rpy="0 0 0"/>
    <axis xyz="0 1 0"/>
    <limit lower="-1.57" upper="1.57" effort="100" velocity="10"/>
  </joint>

  <link name="left_calf_link">
    <visual>
      <geometry>
        <cylinder radius="0.03" length="0.2"/> </geometry>
      <origin xyz="0 0 -0.1" rpy="0 0 0"/>
      <material name="magenta"/>
    </visual>
    <collision>
      <geometry>
        <cylinder radius="0.03" length="0.2"/> </geometry>
      <origin xyz="0 0 -0.1" rpy="0 0 0"/>
    </collision>
    <inertial>
      <mass value="0.7"/>
      <origin xyz="0 0 -0.1"/>
      <inertia ixx="0.003" ixy="0" ixz="0" iyy="0.003" iyz="0" izz="0.00005"/>
    </inertial>
  </link>
  <joint name="left_ankle_joint" type="revolute">
    <parent link="left_thigh_link"/>
    <child link="left_calf_link"/>
    <origin xyz="0 0 -0.25" rpy="0 0 0"/>
    <axis xyz="0 1 0"/>
    <limit lower="-1.57" upper="1.57" effort="100" velocity="10"/>
  </joint>

</robot>